[2023-05-08T23:12:57.075+0000] {taskinstance.py:1125} INFO - Dependencies all met for dep_context=non-requeueable deps ti=<TaskInstance: veryfi_extract_total.extract_and_load scheduled__2023-05-08T00:10:00+00:00 [queued]>
[2023-05-08T23:12:57.136+0000] {taskinstance.py:1125} INFO - Dependencies all met for dep_context=requeueable deps ti=<TaskInstance: veryfi_extract_total.extract_and_load scheduled__2023-05-08T00:10:00+00:00 [queued]>
[2023-05-08T23:12:57.137+0000] {taskinstance.py:1331} INFO - Starting attempt 2 of 2
[2023-05-08T23:12:57.205+0000] {taskinstance.py:1350} INFO - Executing <Task(PythonOperator): extract_and_load> on 2023-05-08 00:10:00+00:00
[2023-05-08T23:12:57.218+0000] {standard_task_runner.py:57} INFO - Started process 329 to run task
[2023-05-08T23:12:57.254+0000] {standard_task_runner.py:84} INFO - Running: ['***', 'tasks', 'run', 'veryfi_extract_total', 'extract_and_load', 'scheduled__2023-05-08T00:10:00+00:00', '--job-id', '58', '--raw', '--subdir', 'DAGS_FOLDER/ml_response_dag.py', '--cfg-path', '/tmp/tmp9p9o5m9k']
[2023-05-08T23:12:57.263+0000] {standard_task_runner.py:85} INFO - Job 58: Subtask extract_and_load
[2023-05-08T23:12:57.700+0000] {task_command.py:410} INFO - Running <TaskInstance: veryfi_extract_total.extract_and_load scheduled__2023-05-08T00:10:00+00:00 [running]> on host 916d3785c91c
[2023-05-08T23:12:58.953+0000] {taskinstance.py:1570} INFO - Exporting env vars: AIRFLOW_CTX_DAG_OWNER='***' AIRFLOW_CTX_DAG_ID='veryfi_extract_total' AIRFLOW_CTX_TASK_ID='extract_and_load' AIRFLOW_CTX_EXECUTION_DATE='2023-05-08T00:10:00+00:00' AIRFLOW_CTX_TRY_NUMBER='2' AIRFLOW_CTX_DAG_RUN_ID='scheduled__2023-05-08T00:10:00+00:00'
[2023-05-08T23:12:59.049+0000] {taskinstance.py:1847} ERROR - Task failed with exception
Traceback (most recent call last):
  File "/home/airflow/.local/lib/python3.7/site-packages/airflow/operators/python.py", line 181, in execute
    return_value = self.execute_callable()
  File "/home/airflow/.local/lib/python3.7/site-packages/airflow/operators/python.py", line 198, in execute_callable
    return self.python_callable(*self.op_args, **self.op_kwargs)
  File "/opt/airflow/dags/ml_response_dag.py", line 31, in extract_total
    cur.execute("INSERT INTO parsed_total (total) VALUES (%s)", (total,))
psycopg2.ProgrammingError: can't adapt type 'dict'
[2023-05-08T23:12:59.167+0000] {taskinstance.py:1373} INFO - Marking task as FAILED. dag_id=veryfi_extract_total, task_id=extract_and_load, execution_date=20230508T001000, start_date=20230508T231257, end_date=20230508T231259
[2023-05-08T23:13:00.076+0000] {standard_task_runner.py:109} ERROR - Failed to execute job 58 for task extract_and_load (can't adapt type 'dict'; 329)
[2023-05-08T23:13:00.726+0000] {local_task_job_runner.py:232} INFO - Task exited with return code 1
[2023-05-08T23:13:01.843+0000] {taskinstance.py:2674} INFO - 0 downstream tasks scheduled from follow-on schedule check
