[2023-05-08T23:13:17.594+0000] {taskinstance.py:1125} INFO - Dependencies all met for dep_context=non-requeueable deps ti=<TaskInstance: veryfi_extract_total.extract_and_load manual__2023-05-08T22:38:37.990646+00:00 [queued]>
[2023-05-08T23:13:25.209+0000] {taskinstance.py:1125} INFO - Dependencies all met for dep_context=requeueable deps ti=<TaskInstance: veryfi_extract_total.extract_and_load manual__2023-05-08T22:38:37.990646+00:00 [queued]>
[2023-05-08T23:13:25.237+0000] {taskinstance.py:1331} INFO - Starting attempt 2 of 2
[2023-05-08T23:13:27.639+0000] {taskinstance.py:1350} INFO - Executing <Task(PythonOperator): extract_and_load> on 2023-05-08 22:38:37.990646+00:00
[2023-05-08T23:13:27.737+0000] {standard_task_runner.py:57} INFO - Started process 355 to run task
[2023-05-08T23:13:27.774+0000] {standard_task_runner.py:84} INFO - Running: ['***', 'tasks', 'run', 'veryfi_extract_total', 'extract_and_load', 'manual__2023-05-08T22:38:37.990646+00:00', '--job-id', '70', '--raw', '--subdir', 'DAGS_FOLDER/ml_response_dag.py', '--cfg-path', '/tmp/tmpx8bfrdvs']
[2023-05-08T23:13:27.778+0000] {standard_task_runner.py:85} INFO - Job 70: Subtask extract_and_load
[2023-05-08T23:13:28.452+0000] {task_command.py:410} INFO - Running <TaskInstance: veryfi_extract_total.extract_and_load manual__2023-05-08T22:38:37.990646+00:00 [running]> on host 916d3785c91c
[2023-05-08T23:13:29.442+0000] {taskinstance.py:1570} INFO - Exporting env vars: AIRFLOW_CTX_DAG_OWNER='***' AIRFLOW_CTX_DAG_ID='veryfi_extract_total' AIRFLOW_CTX_TASK_ID='extract_and_load' AIRFLOW_CTX_EXECUTION_DATE='2023-05-08T22:38:37.990646+00:00' AIRFLOW_CTX_TRY_NUMBER='2' AIRFLOW_CTX_DAG_RUN_ID='manual__2023-05-08T22:38:37.990646+00:00'
[2023-05-08T23:13:29.578+0000] {taskinstance.py:1847} ERROR - Task failed with exception
Traceback (most recent call last):
  File "/home/airflow/.local/lib/python3.7/site-packages/airflow/operators/python.py", line 181, in execute
    return_value = self.execute_callable()
  File "/home/airflow/.local/lib/python3.7/site-packages/airflow/operators/python.py", line 198, in execute_callable
    return self.python_callable(*self.op_args, **self.op_kwargs)
  File "/opt/airflow/dags/ml_response_dag.py", line 31, in extract_total
    cur.execute("INSERT INTO parsed_total (total) VALUES (%s)", (total,))
psycopg2.ProgrammingError: can't adapt type 'dict'
[2023-05-08T23:13:29.687+0000] {taskinstance.py:1373} INFO - Marking task as FAILED. dag_id=veryfi_extract_total, task_id=extract_and_load, execution_date=20230508T223837, start_date=20230508T231317, end_date=20230508T231329
[2023-05-08T23:13:29.790+0000] {standard_task_runner.py:109} ERROR - Failed to execute job 70 for task extract_and_load (can't adapt type 'dict'; 355)
[2023-05-08T23:13:30.105+0000] {local_task_job_runner.py:232} INFO - Task exited with return code 1
[2023-05-08T23:13:30.339+0000] {taskinstance.py:2674} INFO - 0 downstream tasks scheduled from follow-on schedule check
