[2023-05-08T22:42:20.726+0000] {taskinstance.py:1125} INFO - Dependencies all met for dep_context=non-requeueable deps ti=<TaskInstance: veryfi_extract_total.extract_and_load manual__2023-05-08T22:38:37.990646+00:00 [queued]>
[2023-05-08T22:42:20.748+0000] {taskinstance.py:1125} INFO - Dependencies all met for dep_context=requeueable deps ti=<TaskInstance: veryfi_extract_total.extract_and_load manual__2023-05-08T22:38:37.990646+00:00 [queued]>
[2023-05-08T22:42:20.749+0000] {taskinstance.py:1331} INFO - Starting attempt 1 of 2
[2023-05-08T22:42:20.786+0000] {taskinstance.py:1350} INFO - Executing <Task(PythonOperator): extract_and_load> on 2023-05-08 22:38:37.990646+00:00
[2023-05-08T22:42:20.815+0000] {standard_task_runner.py:57} INFO - Started process 232 to run task
[2023-05-08T22:42:20.828+0000] {standard_task_runner.py:84} INFO - Running: ['***', 'tasks', 'run', 'veryfi_extract_total', 'extract_and_load', 'manual__2023-05-08T22:38:37.990646+00:00', '--job-id', '44', '--raw', '--subdir', 'DAGS_FOLDER/ml_response_dag.py', '--cfg-path', '/tmp/tmpv6xkgd17']
[2023-05-08T22:42:20.831+0000] {standard_task_runner.py:85} INFO - Job 44: Subtask extract_and_load
[2023-05-08T22:42:21.108+0000] {task_command.py:410} INFO - Running <TaskInstance: veryfi_extract_total.extract_and_load manual__2023-05-08T22:38:37.990646+00:00 [running]> on host 916d3785c91c
[2023-05-08T22:42:21.532+0000] {taskinstance.py:1570} INFO - Exporting env vars: AIRFLOW_CTX_DAG_OWNER='***' AIRFLOW_CTX_DAG_ID='veryfi_extract_total' AIRFLOW_CTX_TASK_ID='extract_and_load' AIRFLOW_CTX_EXECUTION_DATE='2023-05-08T22:38:37.990646+00:00' AIRFLOW_CTX_TRY_NUMBER='1' AIRFLOW_CTX_DAG_RUN_ID='manual__2023-05-08T22:38:37.990646+00:00'
[2023-05-08T22:42:21.543+0000] {taskinstance.py:1847} ERROR - Task failed with exception
Traceback (most recent call last):
  File "/home/airflow/.local/lib/python3.7/site-packages/airflow/operators/python.py", line 181, in execute
    return_value = self.execute_callable()
  File "/home/airflow/.local/lib/python3.7/site-packages/airflow/operators/python.py", line 198, in execute_callable
    return self.python_callable(*self.op_args, **self.op_kwargs)
  File "/opt/airflow/dags/ml_response_dag.py", line 22, in extract_total
    password="airflow"
  File "/home/airflow/.local/lib/python3.7/site-packages/psycopg2/__init__.py", line 122, in connect
    conn = _connect(dsn, connection_factory=connection_factory, **kwasync)
psycopg2.OperationalError: connection to server at "localhost" (127.0.0.1), port 5432 failed: Connection refused
	Is the server running on that host and accepting TCP/IP connections?
connection to server at "localhost" (::1), port 5432 failed: Cannot assign requested address
	Is the server running on that host and accepting TCP/IP connections?

[2023-05-08T22:42:21.599+0000] {taskinstance.py:1373} INFO - Marking task as UP_FOR_RETRY. dag_id=veryfi_extract_total, task_id=extract_and_load, execution_date=20230508T223837, start_date=20230508T224220, end_date=20230508T224221
[2023-05-08T22:42:21.647+0000] {standard_task_runner.py:109} ERROR - Failed to execute job 44 for task extract_and_load (connection to server at "localhost" (127.0.0.1), port 5432 failed: Connection refused
	Is the server running on that host and accepting TCP/IP connections?
connection to server at "localhost" (::1), port 5432 failed: Cannot assign requested address
	Is the server running on that host and accepting TCP/IP connections?
; 232)
[2023-05-08T22:42:21.699+0000] {local_task_job_runner.py:232} INFO - Task exited with return code 1
[2023-05-08T22:42:21.764+0000] {taskinstance.py:2674} INFO - 0 downstream tasks scheduled from follow-on schedule check
