[2023-05-08T23:13:13.966+0000] {taskinstance.py:1125} INFO - Dependencies all met for dep_context=non-requeueable deps ti=<TaskInstance: veryfi_extract_total.extract_and_load scheduled__2023-05-08T00:08:30+00:00 [queued]>
[2023-05-08T23:13:15.432+0000] {taskinstance.py:1125} INFO - Dependencies all met for dep_context=requeueable deps ti=<TaskInstance: veryfi_extract_total.extract_and_load scheduled__2023-05-08T00:08:30+00:00 [queued]>
[2023-05-08T23:13:15.509+0000] {taskinstance.py:1331} INFO - Starting attempt 2 of 2
[2023-05-08T23:13:17.347+0000] {taskinstance.py:1350} INFO - Executing <Task(PythonOperator): extract_and_load> on 2023-05-08 00:08:30+00:00
[2023-05-08T23:13:17.599+0000] {standard_task_runner.py:57} INFO - Started process 352 to run task
[2023-05-08T23:13:18.324+0000] {standard_task_runner.py:84} INFO - Running: ['***', 'tasks', 'run', 'veryfi_extract_total', 'extract_and_load', 'scheduled__2023-05-08T00:08:30+00:00', '--job-id', '67', '--raw', '--subdir', 'DAGS_FOLDER/ml_response_dag.py', '--cfg-path', '/tmp/tmpbetvj2cy']
[2023-05-08T23:13:18.459+0000] {standard_task_runner.py:85} INFO - Job 67: Subtask extract_and_load
[2023-05-08T23:13:27.880+0000] {task_command.py:410} INFO - Running <TaskInstance: veryfi_extract_total.extract_and_load scheduled__2023-05-08T00:08:30+00:00 [running]> on host 916d3785c91c
[2023-05-08T23:13:28.857+0000] {taskinstance.py:1570} INFO - Exporting env vars: AIRFLOW_CTX_DAG_OWNER='***' AIRFLOW_CTX_DAG_ID='veryfi_extract_total' AIRFLOW_CTX_TASK_ID='extract_and_load' AIRFLOW_CTX_EXECUTION_DATE='2023-05-08T00:08:30+00:00' AIRFLOW_CTX_TRY_NUMBER='2' AIRFLOW_CTX_DAG_RUN_ID='scheduled__2023-05-08T00:08:30+00:00'
[2023-05-08T23:13:28.950+0000] {taskinstance.py:1847} ERROR - Task failed with exception
Traceback (most recent call last):
  File "/home/airflow/.local/lib/python3.7/site-packages/airflow/operators/python.py", line 181, in execute
    return_value = self.execute_callable()
  File "/home/airflow/.local/lib/python3.7/site-packages/airflow/operators/python.py", line 198, in execute_callable
    return self.python_callable(*self.op_args, **self.op_kwargs)
  File "/opt/airflow/dags/ml_response_dag.py", line 31, in extract_total
    cur.execute("INSERT INTO parsed_total (total) VALUES (%s)", (total,))
psycopg2.ProgrammingError: can't adapt type 'dict'
[2023-05-08T23:13:29.034+0000] {taskinstance.py:1373} INFO - Marking task as FAILED. dag_id=veryfi_extract_total, task_id=extract_and_load, execution_date=20230508T000830, start_date=20230508T231314, end_date=20230508T231329
[2023-05-08T23:13:29.301+0000] {standard_task_runner.py:109} ERROR - Failed to execute job 67 for task extract_and_load (can't adapt type 'dict'; 352)
[2023-05-08T23:13:29.614+0000] {local_task_job_runner.py:232} INFO - Task exited with return code 1
[2023-05-08T23:13:29.797+0000] {taskinstance.py:2674} INFO - 0 downstream tasks scheduled from follow-on schedule check
