[2023-05-08T22:42:05.880+0000] {taskinstance.py:1125} INFO - Dependencies all met for dep_context=non-requeueable deps ti=<TaskInstance: veryfi_extract_total.create_table scheduled__2023-05-08T00:06:00+00:00 [queued]>
[2023-05-08T22:42:05.919+0000] {taskinstance.py:1125} INFO - Dependencies all met for dep_context=requeueable deps ti=<TaskInstance: veryfi_extract_total.create_table scheduled__2023-05-08T00:06:00+00:00 [queued]>
[2023-05-08T22:42:05.920+0000] {taskinstance.py:1331} INFO - Starting attempt 2 of 2
[2023-05-08T22:42:05.932+0000] {taskinstance.py:1350} INFO - Executing <Task(PostgresOperator): create_table> on 2023-05-08 00:06:00+00:00
[2023-05-08T22:42:05.944+0000] {standard_task_runner.py:57} INFO - Started process 203 to run task
[2023-05-08T22:42:05.964+0000] {standard_task_runner.py:84} INFO - Running: ['***', 'tasks', 'run', 'veryfi_extract_total', 'create_table', 'scheduled__2023-05-08T00:06:00+00:00', '--job-id', '36', '--raw', '--subdir', 'DAGS_FOLDER/ml_response_dag.py', '--cfg-path', '/tmp/tmpzn6w4yo5']
[2023-05-08T22:42:05.965+0000] {standard_task_runner.py:85} INFO - Job 36: Subtask create_table
[2023-05-08T22:42:14.419+0000] {task_command.py:410} INFO - Running <TaskInstance: veryfi_extract_total.create_table scheduled__2023-05-08T00:06:00+00:00 [running]> on host 916d3785c91c
[2023-05-08T22:42:15.170+0000] {taskinstance.py:1570} INFO - Exporting env vars: AIRFLOW_CTX_DAG_OWNER='***' AIRFLOW_CTX_DAG_ID='veryfi_extract_total' AIRFLOW_CTX_TASK_ID='create_table' AIRFLOW_CTX_EXECUTION_DATE='2023-05-08T00:06:00+00:00' AIRFLOW_CTX_TRY_NUMBER='2' AIRFLOW_CTX_DAG_RUN_ID='scheduled__2023-05-08T00:06:00+00:00'
[2023-05-08T22:42:15.174+0000] {sql.py:262} INFO - Executing: CREATE TABLE IF NOT EXISTS parsed_total (id SERIAL PRIMARY KEY, total FLOAT);
[2023-05-08T22:42:15.547+0000] {taskinstance.py:1847} ERROR - Task failed with exception
Traceback (most recent call last):
  File "/home/airflow/.local/lib/python3.7/site-packages/airflow/providers/common/sql/operators/sql.py", line 263, in execute
    hook = self.get_db_hook()
  File "/home/airflow/.local/lib/python3.7/site-packages/airflow/providers/common/sql/operators/sql.py", line 181, in get_db_hook
    return self._hook
  File "/home/airflow/.local/lib/python3.7/site-packages/cached_property.py", line 36, in __get__
    value = obj.__dict__[self.func.__name__] = self.func(obj)
  File "/home/airflow/.local/lib/python3.7/site-packages/airflow/providers/common/sql/operators/sql.py", line 143, in _hook
    conn = BaseHook.get_connection(self.conn_id)
  File "/home/airflow/.local/lib/python3.7/site-packages/airflow/hooks/base.py", line 72, in get_connection
    conn = Connection.get_connection_from_secrets(conn_id)
  File "/home/airflow/.local/lib/python3.7/site-packages/airflow/models/connection.py", line 434, in get_connection_from_secrets
    raise AirflowNotFoundException(f"The conn_id `{conn_id}` isn't defined")
airflow.exceptions.AirflowNotFoundException: The conn_id `postgres` isn't defined
[2023-05-08T22:42:15.587+0000] {taskinstance.py:1373} INFO - Marking task as FAILED. dag_id=veryfi_extract_total, task_id=create_table, execution_date=20230508T000600, start_date=20230508T224205, end_date=20230508T224215
[2023-05-08T22:42:15.671+0000] {standard_task_runner.py:109} ERROR - Failed to execute job 36 for task create_table (The conn_id `postgres` isn't defined; 203)
[2023-05-08T22:42:15.730+0000] {local_task_job_runner.py:232} INFO - Task exited with return code 1
[2023-05-08T22:42:15.924+0000] {taskinstance.py:2674} INFO - 0 downstream tasks scheduled from follow-on schedule check
