[2023-05-08T22:37:02.736+0000] {taskinstance.py:1125} INFO - Dependencies all met for dep_context=non-requeueable deps ti=<TaskInstance: veryfi_extract_total.create_table scheduled__2023-05-08T00:05:00+00:00 [queued]>
[2023-05-08T22:37:02.790+0000] {taskinstance.py:1125} INFO - Dependencies all met for dep_context=requeueable deps ti=<TaskInstance: veryfi_extract_total.create_table scheduled__2023-05-08T00:05:00+00:00 [queued]>
[2023-05-08T22:37:02.792+0000] {taskinstance.py:1331} INFO - Starting attempt 1 of 2
[2023-05-08T22:37:02.892+0000] {taskinstance.py:1350} INFO - Executing <Task(PostgresOperator): create_table> on 2023-05-08 00:05:00+00:00
[2023-05-08T22:37:02.906+0000] {standard_task_runner.py:57} INFO - Started process 84 to run task
[2023-05-08T22:37:02.950+0000] {standard_task_runner.py:84} INFO - Running: ['***', 'tasks', 'run', 'veryfi_extract_total', 'create_table', 'scheduled__2023-05-08T00:05:00+00:00', '--job-id', '18', '--raw', '--subdir', 'DAGS_FOLDER/ml_response_dag.py', '--cfg-path', '/tmp/tmp11lvu4xo']
[2023-05-08T22:37:02.951+0000] {standard_task_runner.py:85} INFO - Job 18: Subtask create_table
[2023-05-08T22:37:03.814+0000] {task_command.py:410} INFO - Running <TaskInstance: veryfi_extract_total.create_table scheduled__2023-05-08T00:05:00+00:00 [running]> on host 916d3785c91c
[2023-05-08T22:37:04.918+0000] {taskinstance.py:1570} INFO - Exporting env vars: AIRFLOW_CTX_DAG_OWNER='***' AIRFLOW_CTX_DAG_ID='veryfi_extract_total' AIRFLOW_CTX_TASK_ID='create_table' AIRFLOW_CTX_EXECUTION_DATE='2023-05-08T00:05:00+00:00' AIRFLOW_CTX_TRY_NUMBER='1' AIRFLOW_CTX_DAG_RUN_ID='scheduled__2023-05-08T00:05:00+00:00'
[2023-05-08T22:37:04.929+0000] {sql.py:262} INFO - Executing: CREATE TABLE IF NOT EXISTS parsed_total (id SERIAL PRIMARY KEY, total FLOAT);
[2023-05-08T22:37:05.045+0000] {taskinstance.py:1847} ERROR - Task failed with exception
Traceback (most recent call last):
  File "/home/airflow/.local/lib/python3.7/site-packages/airflow/providers/common/sql/operators/sql.py", line 263, in execute
    hook = self.get_db_hook()
  File "/home/airflow/.local/lib/python3.7/site-packages/airflow/providers/common/sql/operators/sql.py", line 181, in get_db_hook
    return self._hook
  File "/home/airflow/.local/lib/python3.7/site-packages/cached_property.py", line 36, in __get__
    value = obj.__dict__[self.func.__name__] = self.func(obj)
  File "/home/airflow/.local/lib/python3.7/site-packages/airflow/providers/common/sql/operators/sql.py", line 143, in _hook
    conn = BaseHook.get_connection(self.conn_id)
  File "/home/airflow/.local/lib/python3.7/site-packages/airflow/hooks/base.py", line 72, in get_connection
    conn = Connection.get_connection_from_secrets(conn_id)
  File "/home/airflow/.local/lib/python3.7/site-packages/airflow/models/connection.py", line 434, in get_connection_from_secrets
    raise AirflowNotFoundException(f"The conn_id `{conn_id}` isn't defined")
airflow.exceptions.AirflowNotFoundException: The conn_id `postgres` isn't defined
[2023-05-08T22:37:05.054+0000] {taskinstance.py:1373} INFO - Marking task as UP_FOR_RETRY. dag_id=veryfi_extract_total, task_id=create_table, execution_date=20230508T000500, start_date=20230508T223702, end_date=20230508T223705
[2023-05-08T22:37:05.110+0000] {standard_task_runner.py:109} ERROR - Failed to execute job 18 for task create_table (The conn_id `postgres` isn't defined; 84)
[2023-05-08T22:37:05.163+0000] {local_task_job_runner.py:232} INFO - Task exited with return code 1
[2023-05-08T22:37:05.431+0000] {taskinstance.py:2674} INFO - 0 downstream tasks scheduled from follow-on schedule check
